<?xml version="1.0"?>
<robot name="myfirst">

<!--Frame -->

  <link name="base_link">
    <visual>
      <origin rpy="0 0 0" xyz="0 0 0"/>
      <geometry>
        <mesh filename="package://heifu/meshes/base_link.dae" scale="0.002 0.002 0.002"/>
      </geometry> 
      <material name="white"/>    
    </visual>
    <collision>
      <origin rpy="0 0 0" xyz="0 0 0"/>
      <geometry>
        <mesh filename="package://heifu/meshes/base_link.dae" scale="0.002 0.002 0.002"/>
      </geometry>
    </collision>
    <inertial>
      <mass value="3.0"/>
      <inertia ixx="0.1" ixy="0.0" ixz="0.0" iyy="0.1" iyz="0.0" izz="0.5"/>
    </inertial>
  </link>

<!--Pernas -->
  <link name="pernas">
    <visual>
      <origin rpy="0 0 0" xyz="0 0 0"/>
      <geometry>
        <mesh filename="package://heifu/meshes/perna.dae" scale="0.002 0.002 0.002"/>
      </geometry> 
      <material name="white"/>    
    </visual>
    <collision>
      <origin rpy="0 0 0" xyz="0 0 0"/>
      <geometry>
        <mesh filename="package://heifu/meshes/perna.dae" scale="0.002 0.002 0.002"/>
      </geometry>
    </collision>
    <inertial>
      <mass value="0.25"/>
      <inertia ixx="0.02" ixy="0.0" ixz="0.0" iyy="0.02" iyz="0.0" izz="0.002"/>
    </inertial>
  </link>

  <link name="pernas2">
    <visual>
      <origin rpy="0 0 0" xyz="0 0 0"/>
      <geometry>
        <mesh filename="package://heifu/meshes/perna.dae" scale="0.002 0.002 0.002"/>
      </geometry> 
      <material name="white"/>    
    </visual>
    <collision>
      <origin rpy="0 0 0" xyz="0 0 0"/>
      <geometry>
        <mesh filename="package://heifu/meshes/perna.dae" scale="0.002 0.002 0.002"/>
      </geometry>
    </collision>
    <inertial>
      <mass value="0.25"/>
      <inertia ixx="0.02" ixy="0.0" ixz="0.0" iyy="0.02" iyz="0.0" izz="0.002"/>
    </inertial>
  </link>


<!--Uniao pernas com frame -->
  <joint name="base_to_leg1" type="fixed">
      <parent link="base_link"/>
      <child link="pernas"/>
      <origin xyz="0.2 0 0" rpy="0 0 0"/>
  </joint>

  <joint name="base_to_leg2" type="fixed">
      <parent link="base_link"/>
      <child link="pernas2"/>
      <origin xyz="-0.2 0 0" rpy="0 0 3.15"/>
  </joint>




<!--Propellers  -->
  <link name="prop1">
    <visual>
      <origin rpy="0 0 0" xyz="0 0 0"/>
      <geometry>
        <mesh filename="package://heifu/meshes/propD.dae" scale="0.002 0.002 0.002"/>
      </geometry> 
      <material name="white"/>    
    </visual>
    <collision>
      <origin rpy="0 0 0" xyz="0 0 0"/>
      <geometry>
        <mesh filename="package://heifu/meshes/propD.dae" scale="0.002 0.002 0.002"/>
      </geometry>
    </collision>
    <inertial>
      <mass value="0.002"/>
      <inertia ixx="9.75e-07" ixy="0.0" ixz="0.0" iyy="0.000326704166667" iyz="0.0" izz="0.000327604166667"/>
    </inertial>
  </link>

  <link name="prop2">
    <visual>
      <origin rpy="0 0 0" xyz="0 0 0"/>
      <geometry>
        <mesh filename="package://heifu/meshes/propD.dae" scale="0.002 0.002 0.002"/>
      </geometry> 
      <material name="white"/>    
    </visual>
    <collision>
      <origin rpy="0 0 0" xyz="0 0 0"/>
      <geometry>
        <mesh filename="package://heifu/meshes/propD.dae" scale="0.002 0.002 0.002"/>
      </geometry>
    </collision>
    <inertial>
      <mass value="0.002"/>
      <inertia ixx="9.75e-07" ixy="0.0" ixz="0.0" iyy="0.000326704166667" iyz="0.0" izz="0.000327604166667"/>
    </inertial>
  </link>

  <link name="prop3">
    <visual>
      <origin rpy="0 0 0" xyz="0 0 0"/>
      <geometry>
        <mesh filename="package://heifu/meshes/propD.dae" scale="0.002 0.002 0.002"/>
      </geometry> 
      <material name="white"/>    
    </visual>
    <collision>
      <origin rpy="0 0 0" xyz="0 0 0"/>
      <geometry>
        <mesh filename="package://heifu/meshes/propD.dae" scale="0.002 0.002 0.002"/>
      </geometry>
    </collision>
    <inertial>
      <mass value="0.002"/>
      <inertia ixx="9.75e-07" ixy="0.0" ixz="0.0" iyy="0.000326704166667" iyz="0.0" izz="0.000327604166667"/>
    </inertial>
  </link>


  <link name="prop4">
    <visual>
      <origin rpy="0 0 0" xyz="0 0 0"/>
      <geometry>
        <mesh filename="package://heifu/meshes/propE.dae" scale="0.002 0.002 0.002"/>
      </geometry> 
      <material name="white"/>    
    </visual>
    <collision>
      <origin rpy="0 0 0" xyz="0 0 0"/>
      <geometry>
        <mesh filename="package://heifu/meshes/propE.dae" scale="0.002 0.002 0.002"/>
      </geometry>
    </collision>
    <inertial>
      <mass value="0.002"/>
      <inertia ixx="9.75e-07" ixy="0.0" ixz="0.0" iyy="0.000326704166667" iyz="0.0" izz="0.000327604166667"/>
    </inertial>
  </link>


  <link name="prop5">
    <visual>
      <origin rpy="0 0 0" xyz="0 0 0"/>
      <geometry>
        <mesh filename="package://heifu/meshes/propE.dae" scale="0.002 0.002 0.002"/>
      </geometry> 
      <material name="white"/>    
    </visual>
    <collision>
      <origin rpy="0 0 0" xyz="0 0 0"/>
      <geometry>
        <mesh filename="package://heifu/meshes/propE.dae" scale="0.002 0.002 0.002"/>
      </geometry>
    </collision>
    <inertial>
      <mass value="0.002"/>
      <inertia ixx="9.75e-07" ixy="0.0" ixz="0.0" iyy="0.000326704166667" iyz="0.0" izz="0.000327604166667"/>
    </inertial>
  </link>


  <link name="prop6">
    <visual>
      <origin rpy="0 0 0" xyz="0 0 0"/>
      <geometry>
        <mesh filename="package://heifu/meshes/propE.dae" scale="0.002 0.002 0.002"/>
      </geometry> 
      <material name="white"/>    
    </visual>
    <collision>
      <origin rpy="0 0 0" xyz="0 0 0"/>
      <geometry>
        <mesh filename="package://heifu/meshes/propE.dae" scale="0.002 0.002 0.002"/>
      </geometry>
    </collision>
    <inertial>
      <mass value="0.002"/>
      <inertia ixx="9.75e-07" ixy="0.0" ixz="0.0" iyy="0.000326704166667" iyz="0.0" izz="0.000327604166667"/>
    </inertial>
  </link>



<!--Uniao propellers com frame -->
  <joint name="base_to_prop1" type="continuous">
      <parent link="base_link"/>
      <child link="prop1"/>
      <origin xyz="0.98 0 0" rpy="0 0 0"/>
      <axis rpy="0 0 0" xyz="0 0 1"/>
  </joint>


  <joint name="base_to_prop2" type="continuous">
      <parent link="base_link"/>
      <child link="prop2"/>
      <origin xyz="-0.49 0.85 0" rpy="0 0 0"/>
      <axis rpy="0 0 0" xyz="0 0 1"/>
  </joint>


  <joint name="base_to_prop3" type="continuous">
      <parent link="base_link"/>
      <child link="prop3"/>
      <origin xyz="-0.49 -0.85 0" rpy="0 0 0"/>
      <axis rpy="0 0 0" xyz="0 0 1"/>
  </joint>
 

  <joint name="base_to_prop4" type="continuous">
      <parent link="base_link"/>
      <child link="prop4"/>
      <origin xyz="-0.98 0 0" rpy="0 0 0"/>
      <axis rpy="0 0 0" xyz="0 0 1"/>
  </joint>


  <joint name="base_to_prop5" type="continuous">
      <parent link="base_link"/>
      <child link="prop5"/>
      <origin xyz="0.49 0.85 0" rpy="0 0 0"/>
      <axis rpy="0 0 0" xyz="0 0 1"/>
  </joint>


  <joint name="base_to_prop6" type="continuous">
      <parent link="base_link"/>
      <child link="prop6"/>
      <origin xyz="0.49 -0.85 0" rpy="0 0 0"/>
      <axis rpy="0 0 0" xyz="0 0 1"/>
  </joint>
 

<!--Plugins de simulacao gazebo -->
  <gazebo>

   <!--Plugin de IMU. Publica Giroscopio e acelerometro -->
   <plugin name="imu_plugin" filename="libgazebo_ros_imu.so">
      <alwaysOn>true</alwaysOn>
      <bodyName>base_link</bodyName>
      <topicName>imu</topicName>
      <serviceName>imu_service</serviceName>
      <gaussianNoise>1.0</gaussianNoise>
      <updateRate>20.0</updateRate>
      <xyzOffsets>0 0 0</xyzOffsets>
      <rpyOffsets>0 0 0</rpyOffsets>
    </plugin>


    <!--Plugin de GPS -->
    <plugin name="gps_controller" filename="libhector_gazebo_ros_gps.so">
      <robotNamespace>myfirst</robotNamespace>
      <updateRate>40</updateRate>
      <bodyName>base_link</bodyName>
      <frameId>base_link</frameId>
      <topicName>gps/fix</topicName>
      <velocityTopicName>navsat/vel</velocityTopicName>
      <referenceLatitude>0.0</referenceLatitude>
      <referenceLongitude>0.0</referenceLongitude>
      <referenceHeading>0</referenceHeading>
      <referenceAltitude>0.8</referenceAltitude>
      <drift>0.001 0.001 0.001</drift>
    </plugin>

    <plugin filename="librotors_gazebo_multirotor_base_plugin.so" name="rosbag">
      <robotNamespace>myfirst</robotNamespace>
      <linkName>base_link</linkName>
      <rotorVelocitySlowdownSim>10</rotorVelocitySlowdownSim>
    </plugin>


    <!--Plugin de controle de velocidade dos motores -->
    <plugin filename="librotors_gazebo_motor_model.so" name="right_motor_model">
      <robotNamespace>myfirst</robotNamespace>
      <jointName>base_to_prop1</jointName>
      <linkName>prop1</linkName>
      <turningDirection>cw</turningDirection>
      <timeConstantUp>0.0</timeConstantUp>
      <timeConstantDown>0.0</timeConstantDown>
      <maxRotVelocity>550</maxRotVelocity>
      <motorConstant>2.39e-05</motorConstant>
      <momentConstant>0.016</momentConstant>
      <commandSubTopic>gazebo/command/motor_speed</commandSubTopic>
      <motorNumber>0</motorNumber>
      <rotorDragCoefficient>1.3858e-06</rotorDragCoefficient>
      <rollingMomentCoefficient>1e-06</rollingMomentCoefficient>
      <motorSpeedPubTopic>motor_speed/0</motorSpeedPubTopic>
      <rotorVelocitySlowdownSim>0.5</rotorVelocitySlowdownSim>
    </plugin>

    <plugin filename="librotors_gazebo_motor_model.so" name="front_left_motor_model">
      <robotNamespace>myfirst</robotNamespace>
      <jointName>base_to_prop2</jointName>
      <linkName>prop2</linkName>
      <turningDirection>cw</turningDirection>
      <timeConstantUp>0.0</timeConstantUp>
      <timeConstantDown>0.0</timeConstantDown>
      <maxRotVelocity>550</maxRotVelocity>
      <motorConstant>2.39e-05</motorConstant>
      <momentConstant>0.016</momentConstant>
      <commandSubTopic>gazebo/command/motor_speed</commandSubTopic>
      <motorNumber>1</motorNumber>
      <rotorDragCoefficient>1.3858e-06</rotorDragCoefficient>
      <rollingMomentCoefficient>1e-06</rollingMomentCoefficient>
      <motorSpeedPubTopic>motor_speed/1</motorSpeedPubTopic>
      <rotorVelocitySlowdownSim>0.5</rotorVelocitySlowdownSim>
    </plugin>

    <plugin filename="librotors_gazebo_motor_model.so" name="back_left_motor_model">
      <robotNamespace>myfirst</robotNamespace>
      <jointName>base_to_prop3</jointName>
      <linkName>prop3</linkName>
      <turningDirection>cw</turningDirection>
      <timeConstantUp>0.0</timeConstantUp>
      <timeConstantDown>0.0</timeConstantDown>
      <maxRotVelocity>550</maxRotVelocity>
      <motorConstant>2.39e-05</motorConstant>
      <momentConstant>0.016</momentConstant>
      <commandSubTopic>gazebo/command/motor_speed</commandSubTopic>
      <motorNumber>2</motorNumber>
      <rotorDragCoefficient>1.3858e-06</rotorDragCoefficient>
      <rollingMomentCoefficient>1e-06</rollingMomentCoefficient>
      <motorSpeedPubTopic>motor_speed/2</motorSpeedPubTopic>
      <rotorVelocitySlowdownSim>0.5</rotorVelocitySlowdownSim>
    </plugin>

    <plugin filename="librotors_gazebo_motor_model.so" name="left_motor_model">
      <robotNamespace>myfirst</robotNamespace>
      <jointName>base_to_prop4</jointName>
      <linkName>prop4</linkName>
      <turningDirection>ccw</turningDirection>
      <timeConstantUp>0.0</timeConstantUp>
      <timeConstantDown>0.0</timeConstantDown>
      <maxRotVelocity>550</maxRotVelocity>
      <motorConstant>2.39e-05</motorConstant>
      <momentConstant>0.016</momentConstant>
      <commandSubTopic>gazebo/command/motor_speed</commandSubTopic>
      <motorNumber>3</motorNumber>
      <rotorDragCoefficient>1.3858e-06</rotorDragCoefficient>
      <rollingMomentCoefficient>1e-06</rollingMomentCoefficient>
      <motorSpeedPubTopic>motor_speed/3</motorSpeedPubTopic>
      <rotorVelocitySlowdownSim>0.5</rotorVelocitySlowdownSim>
    </plugin>


    <plugin filename="librotors_gazebo_motor_model.so" name="front_right_motor_model">
      <robotNamespace>myfirst</robotNamespace>
      <jointName>base_to_prop5</jointName>
      <linkName>prop5</linkName>
      <turningDirection>ccw</turningDirection>
      <timeConstantUp>0.0</timeConstantUp>
      <timeConstantDown>0.0</timeConstantDown>
      <maxRotVelocity>550</maxRotVelocity>
      <motorConstant>2.39e-05</motorConstant>
      <momentConstant>0.016</momentConstant>
      <commandSubTopic>gazebo/command/motor_speed</commandSubTopic>
      <motorNumber>4</motorNumber>
      <rotorDragCoefficient>1.3858e-06</rotorDragCoefficient>
      <rollingMomentCoefficient>1e-06</rollingMomentCoefficient>
      <motorSpeedPubTopic>motor_speed/4</motorSpeedPubTopic>
      <rotorVelocitySlowdownSim>0.5</rotorVelocitySlowdownSim>
    </plugin>



    <plugin filename="librotors_gazebo_motor_model.so" name="back_right_motor_model">
      <robotNamespace>myfirst</robotNamespace>
      <jointName>base_to_prop6</jointName>
      <linkName>prop6</linkName>
      <turningDirection>ccw</turningDirection>
      <timeConstantUp>0.0</timeConstantUp>
      <timeConstantDown>0.0</timeConstantDown>
      <maxRotVelocity>550</maxRotVelocity>
      <motorConstant>2.39e-05</motorConstant>
      <momentConstant>0.016</momentConstant>
      <commandSubTopic>gazebo/command/motor_speed</commandSubTopic>
      <motorNumber>5</motorNumber>
      <rotorDragCoefficient>1.3858e-06</rotorDragCoefficient>
      <rollingMomentCoefficient>1e-06</rollingMomentCoefficient>
      <motorSpeedPubTopic>motor_speed/5</motorSpeedPubTopic>
      <rotorVelocitySlowdownSim>0.5</rotorVelocitySlowdownSim>
    </plugin>
  

  </gazebo>
</robot>
